Workbook

Sheet Cover
B2: SUN PHARMA / ORGANON
B3: Integrated M&A Model — Valuation · Merger · Risk
B4: $14.00/share all-cash · EV ~$11.75bn · expected close early 2027
B6: KEY OUTPUTS
B7: Enterprise value ($mm) | C7: =DCF!C21 -> 12382.623
B8: Equity value ($mm) | C8: =DCF!C23 -> 4282.6226
B9: Equity value per share ($) | C9: =DCF!C25 -> 16.471625
B10: Premium/(discount) to offer | C10: =DCF!C27 -> 0.17654467
B11: WACC (base) | C11: =Assumptions!C27 -> 0.0900325
B12: Goodwill created ($mm) | C12: =PPA!C9 -> 1320
B13: Year-1 EPS accretion | C13: =Accretion!C17 -> 0.59542254
B14: Year-3 EPS accretion | C14: =Accretion!E17 -> 0.75070423
B16: TABS
B17: Instructions · Assumptions · Historicals · DCF · Sensitivity · Trading Comps · Precedents · Sources & Uses · PPA · Debt Schedule · Accretion · Football Field · Risk Register
B21: Confidential — educational purposes only. Analyst estimates; see report Ch.6-9 for sources.

Sheet Instructions
B2: Instructions
B4: COLOUR CONVENTION
B5: Blue = hardcoded input / assumption (edit these).
B6: Black = formula.
B7: Green = link to another sheet.
B9: HOW TO USE
B10: 1. All inputs live on the Assumptions tab. Change any blue cell and the whole model recomputes.
B11: 2. DCF, Sensitivity, Comps and Precedents value Organon standalone; Football Field summarises them.
B12: 3. Sources & Uses, PPA, Debt Schedule and Accretion form the merger model (acquirer = Sun Pharma).
B13: 4. Historicals holds five years of Sun and Organon actuals with computed ratios.
B14: 5. Risk Register scores risks (Probability x Impact).
B16: KEY CONVENTIONS
... B19: All figures are analyst estimates anchored on FY2025 actuals; primary sources in 05_Data/DATA_SOURCES.docx.

Sheet Assumptions
B2: Assumptions
B3: Blue = input · Black = formula · Green = link
B5: OPERATING (Organon, US$ mm)
B6: Base revenue FY2025 | C6: 6216
B7: EBITDA margin | C7: 0.3
B8: D&A | C8: 300
B9: Capex | C9: 160
B10: Change in NWC | C10: 40
B11: Tax rate | C11: 0.19
B12: Terminal exit EV/EBITDA | C12: 6
B13: Revenue growth by year
B14: (Yr1..Yr5) | C14: -0.02 | D14: -0.01 | E14: 0 | F14: 0.01 | G14: 0.01
B16: WACC
B17: Risk-free rate | C17: 0.045
B18: Equity risk premium | C18: 0.055
B19: Beta | C19: 1.05
B20: Cost of equity (CAPM) | C20: =C17+C19*C18 -> 0.10275
B21: Pre-tax cost of debt | C21: 0.07
B22: After-tax cost of debt | C22: =C21*(1-C11) -> 0.0567
B23: Weight equity | C23: 0.65
B24: Weight debt | C24: 0.35
B25: WACC (CAPM) | C25: =C23*C20+C24*C22 -> 0.0866325
B26: Company-specific premium | C26: 0.0034
B27: WACC (base case) | C27: =C25+C26 -> 0.0900325
B29: CAPITALISATION
B30: Shares outstanding (mm) | C30: 260
B31: Net debt | C31: 8100
B32: Offer price ($/share) | C32: 14
B34: MERGER INPUTS
B35: FX (INR per USD) | C35: 85.5
B36: Sun net income | C36: 1278
B37: Sun shares (mm) | C37: 2399.3
B38: Organon adj. net income | C38: 954
B39: Organon existing interest (pre-tax) | C39: 450
B40: Sun EBITDA | C40: 1765
B41: Organon EBITDA | C41: 1910
B42: New acquisition debt | C42: 9500
B43: Blended debt rate | C43: 0.06
B44: Sun cash used | C44: 2250
B45: Forgone rate on cash | C45: 0.04
...

Sheet Historicals
B2: Five-Year Historicals
B4: Sun Pharma (INR crore, Mar-YE)
C5: FY21 | D5: FY22 | E5: FY23 | F5: FY24 | G5: FY25
B6: Revenue | C6: 33498 | D6: 38654 | E6: 43279 | F6: 48497 | G6: 52041
B7: EBITDA | C7: 8040 | D7: 9664 | E7: 11647 | F7: 13337 | G7: 15092
B8: EBITDA margin | C8: =C7/C6 -> 0.24001433 | D8: =D7/D6 -> 0.25001294 | E8: =E7/E6 -> 0.26911435 | F8: =F7/F6 -> 0.2750067 | G8: =G7/G6 -> 0.29000211
B9: Net profit | C9: 2904 | D9: 3273 | E9: 8474 | F9: 9576 | G9: 10929
B10: Net margin | C10: =C9/C6 -> 0.086691743 | D10: =D9/D6 -> 0.08467429 | E10: =E9/E6 -> 0.19579935 | F10: =F9/F6 -> 0.19745551 | G10: =G9/G6 -> 0.21000749
B12: Organon (US$ mm, Dec-YE)
C13: 2021 | D13: 2022 | E13: 2023 | F13: 2024 | G13: 2025
B14: Revenue | C14: 6304 | D14: 6174 | E14: 6263 | F14: 6403 | G14: 6216
B15: Adj. EBITDA | C15: 2270 | D15: 2100 | E15: 1900 | F15: 1960 | G15: 1910
B16: Adj. EBITDA margin | C16: =C15/C14 -> 0.36008883 | D16: =D15/D14 -> 0.34013605 | E16: =E15/E14 -> 0.30336899 | F16: =F15/F14 -> 0.30610651 | G16: =G15/G14 -> 0.30727156
B17: Gross debt | C17: 9134 | D17: 8913 | E17: 8900 | F17: 8880 | G17: 8640
B18: Cash | C18: 737 | D18: 706 | E18: 650 | F18: 690 | G18: 574
B19: Net debt | C19: =C17-C18 -> 8397 | D19: =D17-D18 -> 8207 | E19: =E17-E18 -> 8250 | F19: =F17-F18 -> 8190 | G19: =G17-G18 -> 8066
B20: Net debt / EBITDA | C20: =C19/C15 -> 3.6991189 | D20: =D19/D15 -> 3.9080952 | E20: =E19/E15 -> 4.3421053 | F20: =F19/F15 -> 4.1785714 | G20: =G19/G15 -> 4.2230366
B22: Sun EBITDA FY21/22/24 approx; FY23 & FY25 reported. Organon adj EBITDA 2021-22 est.

Sheet DCF
B2: Discounted Cash Flow (US$ mm)
B3: US$ mm | C3: 2026 | D3: 2027 | E3: 2028 | F3: 2029 | G3: 2030
B4: Period | C4: 1 | D4: 2 | E4: 3 | F4: 4 | G4: 5
B5: Revenue | C5: =Assumptions!$C$6*(1+Assumptions!C14) -> 6091.68 | D5: =C5*(1+Assumptions!D14) -> 6030.7632 | E5: =D5*(1+Assumptions!E14) -> 6030.7632 | F5: =E5*(1+Assumptions!F14) -> 6091.0708 | G5: =F5*(1+Assumptions!G14) -> 6151.9815
B6: EBITDA | C6: =C5*Assumptions!$C$7 -> 1827.504 | D6: =D5*Assumptions!$C$7 -> 1809.229 | E6: =E5*Assumptions!$C$7 -> 1809.229 | F6: =F5*Assumptions!$C$7 -> 1827.3212 | G6: =G5*Assumptions!$C$7 -> 1845.5945
B7: less: D&A | C7: =-Assumptions!$C$8 -> -300 | D7: =-Assumptions!$C$8 -> -300 | E7: =-Assumptions!$C$8 -> -300 | F7: =-Assumptions!$C$8 -> -300 | G7: =-Assumptions!$C$8 -> -300
B8: EBIT | C8: =C6+C7 -> 1527.504 | D8: =D6+D7 -> 1509.229 | E8: =E6+E7 -> 1509.229 | F8: =F6+F7 -> 1527.3212 | G8: =G6+G7 -> 1545.5945
B9: NOPAT | C9: =C8*(1-Assumptions!$C$11) -> 1237.2782 | D9: =D8*(1-Assumptions!$C$11) -> 1222.4755 | E9: =E8*(1-Assumptions!$C$11) -> 1222.4755 | F9: =F8*(1-Assumptions!$C$11) -> 1237.1302 | G9: =G8*(1-Assumptions!$C$11) -> 1251.9315
B10: add: D&A | C10: =Assumptions!$C$8 -> 300 | D10: =Assumptions!$C$8 -> 300 | E10: =Assumptions!$C$8 -> 300 | F10: =Assumptions!$C$8 -> 300 | G10: =Assumptions!$C$8 -> 300
B11: less: Capex | C11: =-Assumptions!$C$9 -> -160 | D11: =-Assumptions!$C$9 -> -160 | E11: =-Assumptions!$C$9 -> -160 | F11: =-Assumptions!$C$9 -> -160 | G11: =-Assumptions!$C$9 -> -160
B12: less: Change in NWC | C12: =-Assumptions!$C$10 -> -40 | D12: =-Assumptions!$C$10 -> -40 | E12: =-Assumptions!$C$10 -> -40 | F12: =-Assumptions!$C$10 -> -40 | G12: =-Assumptions!$C$10 -> -40
B13: Unlevered FCF | C13: =C9+C10+C11+C12 -> 1337.2782 | D13: =D9+D10+D11+D12 -> 1322.4755 | E13: =E9+E10+E11+E12 -> 1322.4755 | F13: =F9+F10+F11+F12 -> 1337.1302 | G13: =G9+G10+G11+G12 -> 1351.9315
B14: Discount factor | C14: =1/(1+Assumptions!$C$27)^C4 -> 0.91740384 | D14: =1/(1+Assumptions!$C$27)^D4 -> 0.8416298 | E14: =1/(1+Assumptions!$C$27)^E4 -> 0.77211441 | F14: =1/(1+Assumptions!$C$27)^F4 -> 0.70834073 | G14: =1/(1+Assumptions!$C$27)^G4 -> 0.6498345
B15: PV of UFCF | C15: =C13*C14 -> 1226.8242 | D15: =D13*D14 -> 1113.0348 | E15: =E13*E14 -> 1021.1024 | F15: =F13*F14 -> 947.14379 | G15: =G13*G14 -> 878.53174
B17: DCF SUMMARY
B18: Sum PV of UFCF (2026-30) | C18: =SUM(C15:G15) -> 5186.6368
B19: Terminal value (exit x EBITDA30) | C19: =Assumptions!$C$12*G6 -> 11073.567
B20: PV of terminal value | C20: =C19*G14 -> 7195.9857
B21: Enterprise value | C21: =C18+C20 -> 12382.623
B22: less: Net debt | C22: =-Assumptions!$C$31 -> -8100
B23: Equity value | C23: =C21+C22 -> 4282.6226
B24: Shares (mm) | C24: =Assumptions!$C$30 -> 260
B25: Equity value per share | C25: =C23/C24 -> 16.471625
B26: Offer price ($/share) | C26: =Assumptions!$C$32 -> 14
B27: Premium/(discount) to offer | C27: =C25/C26-1 -> 0.17654467

Sheet Sensitivity
B2: DCF Sensitivity — Equity Value / Share ($)
B4: Exit \ WACC | C4: 0.08 | D4: 0.085 | E4: 0.09 | F4: 0.095 | G4: 0.1
B5: 5 | C5: =(SUMPRODUCT(DCF!$C$13:$G$13,(1+C$4)^(-DCF!$C$4:$G$4))+$B5*DCF!$G$6*(1+C$4)^(-5)-Assumptions!$C$31)/Assumptions!$C$30 -> 13.481497 | D5: =(SUMPRODUCT(DCF!$C$13:$G$13,(1+D$4)^(-DCF!$C$4:$G$4))+$B5*DCF!$G$6*(1+D$4)^(-5)-Assumptions!$C$31)/Assumptions!$C$30 -> 12.662425 | E5: =(SUMPRODUCT(DCF!$C$13:$G$13,(1+E$4)^(-DCF!$C$4:$G$4))+$B5*DCF!$G$6*(1+E$4)^(-5)-Assumptions!$C$31)/Assumptions!$C$30 -> 11.863938 | F5: =(SUMPRODUCT(DCF!$C$13:$G$13,(1+F$4)^(-DCF!$C$4:$G$4))+$B5*DCF!$G$6*(1+F$4)^(-5)-Assumptions!$C$31)/Assumptions!$C$30 -> 11.085412 | G5: =(SUMPRODUCT(DCF!$C$13:$G$13,(1+G$4)^(-DCF!$C$4:$G$4))+$B5*DCF!$G$6*(1+G$4)^(-5)-Assumptions!$C$31)/Assumptions!$C$30 -> 10.326245
B6: 5.5 | C6: =(SUMPRODUCT(DCF!$C$13:$G$13,(1+C$4)^(-DCF!$C$4:$G$4))+$B6*DCF!$G$6*(1+C$4)^(-5)-Assumptions!$C$31)/Assumptions!$C$30 -> 15.897036 | D6: =(SUMPRODUCT(DCF!$C$13:$G$13,(1+D$4)^(-DCF!$C$4:$G$4))+$B6*DCF!$G$6*(1+D$4)^(-5)-Assumptions!$C$31)/Assumptions!$C$30 -> 15.022817 | E6: =(SUMPRODUCT(DCF!$C$13:$G$13,(1+E$4)^(-DCF!$C$4:$G$4))+$B6*DCF!$G$6*(1+E$4)^(-5)-Assumptions!$C$31)/Assumptions!$C$30 -> 14.170688 | F6: =(SUMPRODUCT(DCF!$C$13:$G$13,(1+F$4)^(-DCF!$C$4:$G$4))+$B6*DCF!$G$6*(1+F$4)^(-5)-Assumptions!$C$31)/Assumptions!$C$30 -> 13.339975 | G6: =(SUMPRODUCT(DCF!$C$13:$G$13,(1+G$4)^(-DCF!$C$4:$G$4))+$B6*DCF!$G$6*(1+G$4)^(-5)-Assumptions!$C$31)/Assumptions!$C$30 -> 12.530031
B7: 6 | C7: =(SUMPRODUCT(DCF!$C$13:$G$13,(1+C$4)^(-DCF!$C$4:$G$4))+$B7*DCF!$G$6*(1+C$4)^(-5)-Assumptions!$C$31)/Assumptions!$C$30 -> 18.312576 | D7: =(SUMPRODUCT(DCF!$C$13:$G$13,(1+D$4)^(-DCF!$C$4:$G$4))+$B7*DCF!$G$6*(1+D$4)^(-5)-Assumptions!$C$31)/Assumptions!$C$30 -> 17.38321 | E7: =(SUMPRODUCT(DCF!$C$13:$G$13,(1+E$4)^(-DCF!$C$4:$G$4))+$B7*DCF!$G$6*(1+E$4)^(-5)-Assumptions!$C$31)/Assumptions!$C$30 -> 16.477437 | F7: =(SUMPRODUCT(DCF!$C$13:$G$13,(1+F$4)^(-DCF!$C$4:$G$4))+$B7*DCF!$G$6*(1+F$4)^(-5)-Assumptions!$C$31)/Assumptions!$C$30 -> 15.594538 | G7: =(SUMPRODUCT(DCF!$C$13:$G$13,(1+G$4)^(-DCF!$C$4:$G$4))+$B7*DCF!$G$6*(1+G$4)^(-5)-Assumptions!$C$31)/Assumptions!$C$30 -> 14.733818
B8: 6.5 | C8: =(SUMPRODUCT(DCF!$C$13:$G$13,(1+C$4)^(-DCF!$C$4:$G$4))+$B8*DCF!$G$6*(1+C$4)^(-5)-Assumptions!$C$31)/Assumptions!$C$30 -> 20.728116 | D8: =(SUMPRODUCT(DCF!$C$13:$G$13,(1+D$4)^(-DCF!$C$4:$G$4))+$B8*DCF!$G$6*(1+D$4)^(-5)-Assumptions!$C$31)/Assumptions!$C$30 -> 19.743602 | E8: =(SUMPRODUCT(DCF!$C$13:$G$13,(1+E$4)^(-DCF!$C$4:$G$4))+$B8*DCF!$G$6*(1+E$4)^(-5)-Assumptions!$C$31)/Assumptions!$C$30 -> 18.784187 | F8: =(SUMPRODUCT(DCF!$C$13:$G$13,(1+F$4)^(-DCF!$C$4:$G$4))+$B8*DCF!$G$6*(1+F$4)^(-5)-Assumptions!$C$31)/Assumptions!$C$30 -> 17.849101 | G8: =(SUMPRODUCT(DCF!$C$13:$G$13,(1+G$4)^(-DCF!$C$4:$G$4))+$B8*DCF!$G$6*(1+G$4)^(-5)-Assumptions!$C$31)/Assumptions!$C$30 -> 16.937604
B9: 7 | C9: =(SUMPRODUCT(DCF!$C$13:$G$13,(1+C$4)^(-DCF!$C$4:$G$4))+$B9*DCF!$G$6*(1+C$4)^(-5)-Assumptions!$C$31)/Assumptions!$C$30 -> 23.143655 | D9: =(SUMPRODUCT(DCF!$C$13:$G$13,(1+D$4)^(-DCF!$C$4:$G$4))+$B9*DCF!$G$6*(1+D$4)^(-5)-Assumptions!$C$31)/Assumptions!$C$30 -> 22.103995 | E9: =(SUMPRODUCT(DCF!$C$13:$G$13,(1+E$4)^(-DCF!$C$4:$G$4))+$B9*DCF!$G$6*(1+E$4)^(-5)-Assumptions!$C$31)/Assumptions!$C$30 -> 21.090936 | F9: =(SUMPRODUCT(DCF!$C$13:$G$13,(1+F$4)^(-DCF!$C$4:$G$4))+$B9*DCF!$G$6*(1+F$4)^(-5)-Assumptions!$C$31)/Assumptions!$C$30 -> 20.103664 | G9: =(SUMPRODUCT(DCF!$C$13:$G$13,(1+G$4)^(-DCF!$C$4:$G$4))+$B9*DCF!$G$6*(1+G$4)^(-5)-Assumptions!$C$31)/Assumptions!$C$30 -> 19.14139

Sheet Trading Comps
B2: Trading Comparables
B4: Organon Adj. EBITDA ($mm) | C4: =Assumptions!C41 -> 1910
B6: Peer | C6: EV/EBITDA
B7: Viatris | C7: 6
B8: Teva | C8: 7.2
B9: Hikma | C9: 7.8
B10: Dr Reddy's | C10: 11
B11: Cipla | C11: 12.5
B13: Relevant range low (x) | C13: 6
B14: Relevant range high (x) | C14: 7.5
B15: Implied equity/share low | C15: =(C13*C4-Assumptions!$C$31)/Assumptions!$C$30 -> 12.923077
B16: Implied equity/share high | C16: =(C14*C4-Assumptions!$C$31)/Assumptions!$C$30 -> 23.942308

Sheet Precedents
B2: Precedent Transactions
B4: Organon Adj. EBITDA ($mm) | C4: ='Trading Comps'!C4 -> 1910
B6: Precedent | C6: EV/EBITDA
B7: Mylan+Upjohn -> Viatris (2020) | C7: 5.5
B8: STADA / Bain-Cinven (2017) | C8: 8
B9: Teva / Allergan Generics (2016) | C9: 10
B11: Relevant range low (x) | C11: 7
B12: Relevant range high (x) | C12: 9
B13: Implied equity/share low | C13: =(C11*C4-Assumptions!$C$31)/Assumptions!$C$30 -> 20.269231
B14: Implied equity/share high | C14: =(C12*C4-Assumptions!$C$31)/Assumptions!$C$30 -> 34.961538

Sheet Sources & Uses
B2: Sources & Uses ($mm)
B4: Sources | D4: Uses
B5: New acquisition debt | C5: =Assumptions!C42 -> 9500 | D5: Refinance Organon debt | E5: 8100
B6: Sun internal accruals (plug) | C6: =E8-C5-C7 -> 2240 | D6: Equity consideration | E6: =Assumptions!C51 -> 3640
B7: Organon cash | C7: 250 | D7: Fees & expenses (est.) | E7: 250
B8: Total sources | C8: =SUM(C5:C7) -> 11990 | D8: Total uses | E8: =SUM(E5:E7) -> 11990
B10: Check (sources - uses) | C10: =C8-E8 -> 0

Sheet PPA
B2: Purchase Price Allocation ($mm)
B4: Equity purchase price | C4: =Assumptions!C51 -> 3640
B5: less: Organon book equity | C5: =-Assumptions!C50 -> -700
B6: Allocable excess | C6: =C4+C5 -> 2940
B7: Identifiable intangible step-up | C7: =Assumptions!C48 -> 2000
B8: Deferred tax liability on step-up | C8: =C7*Assumptions!C11 -> 380
B9: Goodwill (plug) | C9: =C6-C7+C8 -> 1320
B11: Incremental amortization, pre-tax | C11: =C7/Assumptions!C49 -> 133.33333
B12: Incremental amortization, after-tax | C12: =C11*(1-Assumptions!C11) -> 108

Sheet Debt Schedule
B2: Debt Schedule ($mm)
B4: Year | C4: Yr 1 | D4: Yr 2 | E4: Yr 3 | F4: Yr 4 | G4: Yr 5
B5: Beginning debt | C5: =Assumptions!C42 -> 9500 | D5: =C9 -> 7700 | E5: =D9 -> 5900 | F5: =E9 -> 4100 | G5: =F9 -> 2300
B6: Interest (opening x rate) | C6: =C5*Assumptions!$C$43 -> 570 | D6: =D5*Assumptions!$C$43 -> 462 | E6: =E5*Assumptions!$C$43 -> 354 | F6: =F5*Assumptions!$C$43 -> 246 | G6: =G5*Assumptions!$C$43 -> 138
B7: FCF sweep (repayment) | C7: =-MIN(Assumptions!$C$52,C5) -> -1800 | D7: =-MIN(Assumptions!$C$52,D5) -> -1800 | E7: =-MIN(Assumptions!$C$52,E5) -> -1800 | F7: =-MIN(Assumptions!$C$52,F5) -> -1800 | G7: =-MIN(Assumptions!$C$52,G5) -> -1800
B8: Synergy add (EBITDA) | C8: =Assumptions!$C$46*Assumptions!C47 -> 105 | D8: =Assumptions!$C$46*Assumptions!D47 -> 245 | E8: =Assumptions!$C$46*Assumptions!E47 -> 350 | F8: =Assumptions!$C$46*Assumptions!E47 -> 350 | G8: =Assumptions!$C$46*Assumptions!E47 -> 350
B9: Ending debt | C9: =C5+C7 -> 7700 | D9: =D5+D7 -> 5900 | E9: =E5+E7 -> 4100 | F9: =F5+F7 -> 2300 | G9: =G5+G7 -> 500
B10: Combined EBITDA | C10: =Assumptions!$C$40+Assumptions!$C$41+C8 -> 3780 | D10: =Assumptions!$C$40+Assumptions!$C$41+D8 -> 3920 | E10: =Assumptions!$C$40+Assumptions!$C$41+E8 -> 4025 | F10: =Assumptions!$C$40+Assumptions!$C$41+F8 -> 4025 | G10: =Assumptions!$C$40+Assumptions!$C$41+G8 -> 4025
B11: Net debt / EBITDA | C11: =C9/C10 -> 2.037037 | D11: =D9/D10 -> 1.505102 | E11: =E9/E10 -> 1.0186335 | F11: =F9/F10 -> 0.57142857 | G11: =G9/G10 -> 0.1242236

Sheet Accretion
B2: Accretion / (Dilution)
C4: Year 1 | D4: Year 2 | E4: Year 3
B5: Sun standalone net income | C5: =Assumptions!$C$36 -> 1278 | D5: =Assumptions!$C$36 -> 1278 | E5: =Assumptions!$C$36 -> 1278
B6: Organon pre-financing earnings (a-t) | C6: =Assumptions!$C$38+Assumptions!$C$39*(1-Assumptions!$C$11) -> 1318.5 | D6: =Assumptions!$C$38+Assumptions!$C$39*(1-Assumptions!$C$11) -> 1318.5 | E6: =Assumptions!$C$38+Assumptions!$C$39*(1-Assumptions!$C$11) -> 1318.5
B7: less: new acquisition interest (a-t) | C7: =-Assumptions!$C$42*Assumptions!$C$43*(1-Assumptions!$C$11) -> -461.7 | D7: =-Assumptions!$C$42*Assumptions!$C$43*(1-Assumptions!$C$11) -> -461.7 | E7: =-Assumptions!$C$42*Assumptions!$C$43*(1-Assumptions!$C$11) -> -461.7
B8: less: forgone interest on cash (a-t) | C8: =-Assumptions!$C$44*Assumptions!$C$45*(1-Assumptions!$C$11) -> -72.9 | D8: =-Assumptions!$C$44*Assumptions!$C$45*(1-Assumptions!$C$11) -> -72.9 | E8: =-Assumptions!$C$44*Assumptions!$C$45*(1-Assumptions!$C$11) -> -72.9
B9: less: incremental PPA amort (a-t) | C9: =-PPA!C12 -> -108 | D9: =-PPA!C12 -> -108 | E9: =-PPA!C12 -> -108
B10: add: synergies (a-t) | C10: =Assumptions!$C$46*Assumptions!C47*(1-Assumptions!$C$11) -> 85.05 | D10: =Assumptions!$C$46*Assumptions!D47*(1-Assumptions!$C$11) -> 198.45 | E10: =Assumptions!$C$46*Assumptions!E47*(1-Assumptions!$C$11) -> 283.5
B11: Pro forma net income | C11: =SUM(C5:C10) -> 2038.95 | D11: =SUM(D5:D10) -> 2152.35 | E11: =SUM(E5:E10) -> 2237.4
B13: Sun standalone EPS ($) | C13: =Assumptions!$C$36/Assumptions!$C$37 -> 0.53265536 | D13: =Assumptions!$C$36/Assumptions!$C$37 -> 0.53265536 | E13: =Assumptions!$C$36/Assumptions!$C$37 -> 0.53265536
B14: Pro forma EPS ($) | C14: =C11/Assumptions!$C$37 -> 0.84981036 | D14: =D11/Assumptions!$C$37 -> 0.89707415 | E14: =E11/Assumptions!$C$37 -> 0.93252199
B15: Sun standalone EPS (INR) | C15: =C13*Assumptions!$C$35 -> 45.542033 | D15: =D13*Assumptions!$C$35 -> 45.542033 | E15: =E13*Assumptions!$C$35 -> 45.542033
B16: Pro forma EPS (INR) | C16: =C14*Assumptions!$C$35 -> 72.658786 | D16: =D14*Assumptions!$C$35 -> 76.69984 | E16: =E14*Assumptions!$C$35 -> 79.73063
B17: Accretion / (dilution) % | C17: =C14/C13-1 -> 0.59542254 | D17: =D14/D13-1 -> 0.68415493 | E17: =E14/E13-1 -> 0.75070423

Sheet Football Field
B2: Football Field — Equity Value / Share ($)
B4: Methodology | C4: Low | D4: High
B5: DCF (WACC 8.5-9.5%, exit 5.5-6.5x) | C5: =Sensitivity!F6 -> 13.339975 | D5: =Sensitivity!D8 -> 19.743602
B6: Trading comps (6.0-7.5x) | C6: ='Trading Comps'!C15 -> 12.923077 | D6: ='Trading Comps'!C16 -> 23.942308
B7: Precedent txns (7.0-9.0x) | C7: =Precedents!C13 -> 20.269231 | D7: =Precedents!C14 -> 34.961538
B8: 52-week trading range | C8: 9 | D8: 22
B10: Offer price ($/share) | C10: =Assumptions!C32 -> 14

Sheet Risk Register
B2: Risk Register
B4: Risk | C4: Category | D4: Probability | E4: Impact | F4: Score | G4: Mitigation
B5: Established-brands decline | C5: Commercial | D5: 4 | E5: 5 | F5: =D5*E5 -> 20 | G5: Mix to WH/biosimilars; low 6.2x entry gives margin of safety
B6: Refinancing / rates | C6: Financing | D6: 3 | E6: 4 | F6: =D6*E6 -> 12 | G6: Committed bridge; term out early; hedge rates
B7: Nexplanon probe / litigation | C7: Litigation | D7: 3 | E7: 4 | F7: =D7*E7 -> 12 | G7: Diligence, reps & warranties, indemnity/escrow
B8: Biosimilar price erosion | C8: Competition | D8: 4 | E8: 3 | F8: =D8*E8 -> 12 | G8: Sun low-cost, API-integrated manufacturing
B9: Cross-border integration | C9: Integration | D9: 3 | E9: 3 | F9: =D9*E9 -> 9 | G9: Integration office; retain Organon team
B10: Synergy shortfall | C10: Execution | D10: 3 | E10: 3 | F10: =D10*E10 -> 9 | G10: Conservative underwrite; phased 30/70/100
B11: Currency (USD/INR) | C11: Currency | D11: 4 | E11: 2 | F11: =D11*E11 -> 8 | G11: USD debt matched to USD cash flows
B12: Regulatory / antitrust | C12: Regulatory | D12: 2 | E12: 3 | F12: =D12*E12 -> 6 | G12: Low overlap; multi-jurisdiction filings
B13: Macroeconomic | C13: Macro | D13: 2 | E13: 3 | F13: =D13*E13 -> 6 | G13: Diversified geography; defensive demand
B14: Technology / pipeline | C14: Technology | D14: 2 | E14: 2 | F14: =D14*E14 -> 4 | G14: Established portfolio; low pipeline reliance
